<?xml version="1.0" encoding="UTF-8"?>
<robot generator="Robot 4.1.3 (Python 3.7.0 on win32)" generated="20220213 14:52:10.084" rpa="false" schemaversion="2">
<suite id="s1" name="Verify Valid" source="C:\Users\Harish banakar\Desktop\LT4\robotframeworkpractice\login_suite\verify_valid.robot">
<test id="s1-t1" name="TC1">
<status status="FAIL" starttime="20220213 14:52:11.972" endtime="20220213 14:52:11.975">Test case contains no keywords.</status>
</test>
<doc>This suite file verifies all test cases related to valid credentials</doc>
<status status="FAIL" starttime="20220213 14:52:10.089" endtime="20220213 14:52:11.986"/>
</suite>
<statistics>
<total>
<stat pass="0" fail="1" skip="0">All Tests</stat>
</total>
<tag>
</tag>
<suite>
<stat pass="0" fail="1" skip="0" id="s1" name="Verify Valid">Verify Valid</stat>
</suite>
</statistics>
<errors>
<msg timestamp="20220213 14:52:11.832" level="ERROR">[ DataDriver ] Error in robot file:
  File "C:\Users\Harish banakar\Desktop\LT4\robotframeworkpractice\login_suite\verify_valid.robot", line 0</msg>
<msg timestamp="20220213 14:52:11.844" level="ERROR">In source file:
  File "C:\Users\Harish banakar\Desktop\LT4\robotframeworkpractice\login_suite\../test_data/openEMRData.xlsx", line 0</msg>
<msg timestamp="20220213 14:52:11.967" level="ERROR">Calling method '_start_suite' of listener 'DataDriver' failed: KeyError: 'Worksheet verify_valid_credentials does not exist.'</msg>
</errors>
</robot>
